<?xml version="1.0" ?>
<robot name="planar3r">
  <!-- base -->
  <link name="base"/>

  <!-- link1 -->
  <link name="link1">
    <inertial><origin xyz="0.5 0 0"/><mass value="1"/><inertia ixx="0.01" iyy="0.01" izz="0.01"/></inertial>
    <visual>
      <origin xyz="0.5 0 0"/>
      <geometry><box size="1 0.05 0.05"/></geometry>
      <material name="red"><color rgba="0.85 0.2 0.2 1"/></material>
    </visual>
    <collision><origin xyz="0.5 0 0"/><geometry><box size="1 0.05 0.05"/></geometry></collision>
  </link>

  <joint name="joint1" type="revolute">
    <parent link="base"/>
    <child  link="link1"/>
    <origin xyz="0 0 0" rpy="0 0 0"/>
    <axis xyz="0 0 1"/>
    <limit lower="-3.14159" upper="3.14159" effort="100" velocity="3"/>
  </joint>

  <!-- link2 -->
  <link name="link2">
    <inertial><origin xyz="0.5 0 0"/><mass value="1"/><inertia ixx="0.01" iyy="0.01" izz="0.01"/></inertial>
    <visual>
      <origin xyz="0.5 0 0"/>
      <geometry><box size="1 0.05 0.05"/></geometry>
      <material name="green"><color rgba="0.2 0.8 0.2 1"/></material>
    </visual>
    <collision><origin xyz="0.5 0 0"/><geometry><box size="1 0.05 0.05"/></geometry></collision>
  </link>

  <joint name="joint2" type="revolute">
    <parent link="link1"/>
    <child  link="link2"/>
    <origin xyz="1 0 0" rpy="0 0 0"/>
    <axis xyz="0 0 1"/>
    <limit lower="-3.14159" upper="3.14159" effort="100" velocity="3"/>
  </joint>

  <!-- link3 -->
  <link name="link3">
    <inertial><origin xyz="0.5 0 0"/><mass value="1"/><inertia ixx="0.01" iyy="0.01" izz="0.01"/></inertial>
    <visual>
      <origin xyz="0.5 0 0"/>
      <geometry><box size="1 0.05 0.05"/></geometry>
      <material name="blue"><color rgba="0.2 0.2 0.85 1"/></material>
    </visual>
    <collision><origin xyz="0.5 0 0"/><geometry><box size="1 0.05 0.05"/></geometry></collision>
  </link>

  <joint name="joint3" type="revolute">
    <parent link="link2"/>
    <child  link="link3"/>
    <origin xyz="1 0 0" rpy="0 0 0"/>
    <axis xyz="0 0 1"/>
    <limit lower="-3.14159" upper="3.14159" effort="100" velocity="3"/>
  </joint>

  <!-- end-effector marker -->
  <link name="ee">
    <visual>
      <origin xyz="0 0 0"/>
      <geometry><sphere radius="0.06"/></geometry>
      <material name="ee"><color rgba="1 0.8 0 1"/></material>
    </visual>
  </link>
  <joint name="ee_fixed" type="fixed">
    <parent link="link3"/>
    <child  link="ee"/>
    <origin xyz="1 0 0" rpy="0 0 0"/>
  </joint>
</robot>